Workbook

Sheet Journals
A1: Problem 21
A2: Journal Entries
A3: Date | B3: Particulars | C3: L.F. | D3: Debit (Rs) | E3: Credit (Rs)
A4: 1.1 | B4: Cash a/c Dr. | D4: 90000
B5: To Capital a/c | E5: 90000
B6: (Being business started with cash)
A8: 1.1 | B8: Stock a/c Dr. | D8: 40000
B9: To Capital a/c | E9: 40000
B10: (Being business started with stocks)
A12: 1.1 | B12: Building a/c Dr. | D12: 100000
B13: To Capital a/c | E13: 100000
B14: (Being business started with building)
A16: 1.1 | B16: Furniture a/c Dr. | D16: 40000
B17: To Capital a/c | E17: 40000
B18: (Being business started with furniture)
A20: 45660 | B20: Printing Machine a/c Dr. | D20: 15000
B21: Laminating Machine a/c Dr. | D21: 20000
B22: To Cash a/c | E22: 35000
B23: (Being printing and lamination machine purchased)
A25: 45662 | B25: Cash a/c Dr. | D25: 2000
B26: To Commission a/c | E26: 2000
B27: (Being commission received from service)
A29: 45664 | B29: Office Supplies a/c Dr. | D29: 2000
B30: To Cash a/c | E30: 2000
B31: (Being office supplies purchased)
A33: 45667 | B33: Rent Expenses a/c Dr. | D33: 40000
B34: To Cash a/c | E34: 40000
B35: (Being office rent paid)
A37: 45670 | B37: Cash a/c Dr. | D37: 11500
B38: To Gain on sale of Furniture a/c | E38: 1500
B39: To Sale of Furniture a/c | E39: 10000
B40: (Being furniture sold on profit)
A42: 45675 | B42: Purchase a/c Dr. | D42: 12000
B43: To Creditor's a/c | E43: 12000
B44: (Being good purchased on credit)
A46: 45679 | B46: Sundry Debtor's a/c Dr. | D46: 5000
B47: To Sales a/c | E47: 5000
B48: (Being goods sold on credit)
A50: 45681 | B50: Creditor's a/c Dr. | D50: 500
B51: To Purchase Return a/c | E51: 500
...

Sheet Ledgers
A1: Cash Account | K1: Capital Account
A2: Dr. | E2: Cr. | K2: Dr. | O2: Cr.
A3: Date | B3: Particulars | C3: JF | D3: Amount | E3: Date | F3: Particulars | G3: JF | H3: Amount | K3: Date | L3: Particulars | M3: JF | N3: Amount | O3: Date | P3: Particulars | Q3: JF | R3: Amount
A4: =Journals!A4 -> 1.1 | B4: =Journals!B5 -> To Capital a/c | D4: =Journals!D4 -> 90000 | E4: =Journals!A29 -> 45664 | F4: By Office Supplies a/c | H4: =Journals!D29 -> 2000 | K4: 45688 | L4: To Balance c/d | N4: 270000 | O4: =Journals!A4 -> 1.1 | P4: By Cash a/c | R4: =Journals!D4 -> 90000
A5: =Journals!A25 -> 45662 | B5: =Journals!B26 -> To Commission a/c | D5: =Journals!D25 -> 2000 | E5: =Journals!A33 -> 45667 | F5: By Rent Expenses a/c | H5: =Journals!D33 -> 40000 | O5: =Journals!A8 -> 1.1 | P5: By Stock a/c | R5: =Journals!D8 -> 40000
A6: =Journals!A37 -> 45670 | B6: =Journals!B38 -> To Gain on sale of Furniture a/c | D6: =Journals!E38 -> 1500 | E6: =Journals!A62 -> 45687 | F6: By Creditor's a/c | H6: =Journals!D62 -> 11300 | O6: =Journals!A12 -> 1.1 | P6: By Building a/c | R6: =Journals!D12 -> 100000
A7: =Journals!A37 -> 45670 | B7: =Journals!B39 -> To Sale of Furniture a/c | D7: =Journals!E39 -> 10000 | E7: =Journals!A20 -> 45660 | F7: By Printing Machine a/c | H7: =Journals!D20 -> 15000 | O7: =Journals!A16 -> 1.1 | P7: By Furniture a/c | R7: =Journals!D16 -> 40000
A8: =Journals!A58 -> 45686 | B8: =Journals!B59 -> To Sundry Debtor's a/c | D8: =Journals!D58 -> 4400 | E8: =Journals!A20 -> 45660 | F8: By Laminating Machine a/c | H8: =Journals!D21 -> 20000 | N8: =SUM(N4:N7) -> 270000 | R8: =SUM(R4:R7) -> 270000
E9: 45688 | F9: By Balance c/d | H9: 19600 | O9: 45689 | P9: By balance b/d | R9: =N8 -> 270000
D10: =SUM(D4:D9) -> 107900 | H10: =SUM(H4:H9) -> 107900
A11: 45689 | B11: To Balance b/d | D11: =H9 -> 19600
A14: Stock Account | K14: Printer Account
A15: Dr. | E15: Cr. | K15: Dr. | O15: Cr.
A16: Date | B16: Particulars | C16: JF | D16: Amount | E16: Date | F16: Particulars | G16: JF | H16: Amount | K16: Date | L16: Particulars | M16: JF | N16: Amount | O16: Date | P16: Particulars | Q16: JF | R16: Amount
A17: =Journals!A8 -> 1.1 | B17: =Journals!B9 -> To Capital a/c | D17: =Journals!D8 -> 40000 | E17: 45688 | F17: By Balance c/d | H17: 40000 | K17: =Journals!A20 -> 45660 | L17: =Journals!B22 -> To Cash a/c | N17: =Journals!D20 -> 15000 | O17: 45688 | P17: By Balance c/d | R17: 15000
D18: =SUM(D17) -> 40000 | H18: =SUM(H17) -> 40000 | N18: =SUM(N17) -> 15000 | R18: =SUM(R17) -> 15000
A19: 45689 | B19: To Balance b/d | D19: 40000 | K19: 45689 | L19: To Balance c/d | N19: =R17 -> 15000
A22: Building Account | K22: Laminating Machine Account
A23: Dr. | E23: Cr. | K23: Dr. | O23: Cr.
A24: Date | B24: Particulars | C24: JF | D24: Amount | E24: Date | F24: Particulars | G24: JF | H24: Amount | K24: Date | L24: Particulars | M24: JF | N24: Amount | O24: Date | P24: Particulars | Q24: JF | R24: Amount
A25: =Journals!A12 -> 1.1 | B25: =Journals!B13 -> To Capital a/c | D25: =Journals!D12 -> 100000 | E25: 45688 | F25: By Balance c/d | H25: 100000 | K25: =Journals!A20 -> 45660 | L25: =Journals!B30 -> To Cash a/c | N25: =Journals!D21 -> 20000 | O25: 45688 | P25: By Balance c/d | R25: 20000
D26: =SUM(D25) -> 100000 | H26: =SUM(H25) -> 100000 | N26: =SUM(N25) -> 20000 | R26: =SUM(R25) -> 20000
A27: 45689 | B27: To Balance b/d | D27: =H25 -> 100000 | K27: 45689 | L27: To Balance c/d | N27: =R25 -> 20000
A30: Furniture Account | K30: Commission Account
A31: Dr. | E31: Cr. | K31: Dr. | O31: Cr.
A32: Date | B32: Particulars | C32: JF | D32: Amount | E32: Date | F32: Particulars | G32: JF | H32: Amount | K32: Date | L32: Particulars | M32: JF | N32: Amount | O32: Date | P32: Particulars | Q32: JF | R32: Amount
A33: =Journals!A16 -> 1.1 | B33: =Journals!B17 -> To Capital a/c | D33: =Journals!D16 -> 40000 | E33: =Journals!A37 -> 45670 | F33: By Sale of Furniture a/c | H33: =Journals!E39 -> 10000 | K33: 45688 | L33: To Balance c/d | N33: =Journals!D29 -> 2000 | O33: =Journals!A25 -> 45662 | P33: By Cash a/c | R33: =Journals!D25 -> 2000
E34: 45688 | F34: By Balance c/d | H34: 30000 | N34: =SUM(N33) -> 2000 | R34: =SUM(R33) -> 2000
D35: =SUM(D33:D34) -> 40000 | H35: =SUM(H33:H34) -> 40000 | O35: 45689 | P35: By Balance b/d | R35: 2000
A36: 45689 | B36: To Balance b/d | D36: =H34 -> 30000
A39: Purchase Account | K39: Office Supplies Account
A40: Dr. | E40: Cr. | K40: Dr. | O40: Cr.
A41: Date | B41: Particulars | C41: JF | D41: Amount | E41: Date | F41: Particulars | G41: JF | H41: Amount | K41: Date | L41: Particulars | M41: JF | N41: Amount | O41: Date | P41: Particulars | Q41: JF | R41: Amount
A42: =Journals!A42 -> 45675 | B42: =Journals!B43 -> To Creditor's a/c | D42: =Journals!D42 -> 12000 | E42: 45688 | F42: By Balance c/d | H42: 12000 | K42: =Journals!A29 -> 45664 | L42: =Journals!B30 -> To Cash a/c | N42: =Journals!D29 -> 2000 | O42: 45688 | P42: By Balance c/d | R42: 2000
D43: =SUM(D42) -> 12000 | H43: =SUM(H42) -> 12000 | N43: =SUM(N42) -> 2000 | R43: =SUM(R42) -> 2000
A44: 45689 | B44: To Balance b/d | D44: 12000 | K44: 45689 | L44: To Balance b/d | N44: 2000
A47: Rent Account | K47: Purchase Return Account
A48: Dr. | E48: Cr. | K48: Dr. | O48: Cr.
A49: Date | B49: Particulars | C49: JF | D49: Amount | E49: Date | F49: Particulars | G49: JF | H49: Amount | K49: Date | L49: Particulars | M49: JF | N49: Amount | O49: Date | P49: Particulars | Q49: JF | R49: Amount
A50: =Journals!A33 -> 45667 | B50: =Journals!B34 -> To Cash a/c | D50: =Journals!D33 -> 40000 | E50: 45688 | F50: By Balance c/d | H50: 40000 | K50: 45688 | L50: To Balance c/d | N50: 500 | O50: =Journals!A50 -> 45681 | P50: By Creditors a/c | R50: =Journals!D50 -> 500
...
